Workbook

Sheet 0.개요
A1: 가스안전 AI 어드바이저 2.0 고도화 — 과제·과업별 SW 예산 견적
A2: 근거: ①27년 신규사업 정부·국회 심의자료(SW 758백만원) ②가스안전 AI 어드바이저 2.0 고도화 추진계획(2026.9, 제도정책부)
A4: ■ 견적 산정 가정 (노란 셀 = 수정 가능 입력값)
A5: 항목 | B5: 값 | C5: 근거/설명
A6: 2025년 적용 응용SW개발자 월평균임금(백만원) | B6: 6.943457 | C6: KOSA 2025년 적용 SW기술자 평균임금 공표(응용SW개발자, 인공지능·빅데이터개발자 포함) 월 6,943,457원
A7: 2026년 임금 인상률(가정) | B7: 0.047 | C7: 2026년 SW기술자 노임단가 전년대비 +4.7%(재게시 자료). KOSA 2026년 적용 원문 공표치로 교체 권장
A8: 제경비율 | B8: 1.1 | C8: SW사업 대가산정 가이드: 직접인건비의 110~120%
A9: 기술료율 | B9: 0.2 | C9: SW사업 대가산정 가이드: (직접인건비+제경비)의 20~40%
A10: 부가가치세율 | B10: 0.1
A11: 27년 SW 예산(백만원, VAT포함) | B11: 758 | C11: 27년 신규사업 정부·국회 심의자료 S/W 예산 합계
A12: 직접인건비 단가(백만원/MM, 2027 적용 추정) | B12: ='0.개요'!$B$6*(1+'0.개요'!$B$7) -> 7.2697995 | C12: 2025 월평균임금 × (1+인상률). 27년 착수 시 2027년 적용 공표치 반영 필요
A13: 투입 M/M 단가(백만원/MM, VAT별도) | B13: ='0.개요'!$B$12*(1+'0.개요'!$B$8)*(1+'0.개요'!$B$9) -> 18.319895 | C13: 직접인건비 × (1+제경비율) × (1+기술료율)
A16: ■ 과제별 견적 요약 (단위: 백만원)
A17: 과제 | B17: 투입 M/M | C17: 금액(VAT별도)
A18: 과제1 가스안전 지식DB 고도화 (데이터 정비) | B18: ='3.견적서'!G5 -> 10 | C18: ='3.견적서'!J5 -> 197.69895
A19: 과제2 스마트온 2.0 연계를 통한 모바일 서비스 제공 | B19: ='3.견적서'!G19 -> 5.5 | C19: ='3.견적서'!J19 -> 150.75942
A20: 과제3 사이버지사 VOC 질의 챗봇 구축 (대국민 서비스) | B20: ='3.견적서'!G31 -> 7.5 | C20: ='3.견적서'!J31 -> 137.39921
A21: 과제4 "정확도"를 넘어 "신뢰성" 확보 (AI 신뢰성 고도화) | B21: ='3.견적서'!G43 -> 7.5 | C21: ='3.견적서'!J43 -> 145.39921
A22: 공통 사업관리 및 품질보증 | B22: ='3.견적서'!G55 -> 3 | C22: ='3.견적서'!J55 -> 54.959684
A23: 공급가액 합계 | C23: ='3.견적서'!J63 -> 686.21647
A24: 부가가치세 | C24: ='3.견적서'!J64 -> 68.621647
A25: 총 견적액(VAT포함) | C25: ='3.견적서'!J65 -> 754.83812
A26: 27년 SW 예산 | C26: ='3.견적서'!J66 -> 758
A27: 예산 대비 차액 | C27: ='3.견적서'!J67 -> 3.1618808
A29: ■ 범례
A30: ● 일치 | C30: 27예산 SW항목과 고도화 기획안 과업이 일치
A31: ◐ 부분일치(범위확대) | C31: 27예산에 있으나 기획안 기준으로 범위 확대·구체화 필요
A32: ★ 기획안에만 있음 | C32: 고도화 기획안에만 있는 과업(27예산 미반영, 신규)
A33: ▲ 27예산에만 있음 | C33: 27예산에만 있는 과업(기획안 로드맵 3단계 '28년)
A34: 파란 글씨 / 노란 셀 | C34: 수정 가능한 입력값(M/M, 단가, 요율). 수정 시 전 시트 자동 재계산
A35: 초록 글씨 | C35: 다른 시트 참조 수식
A37: ■ 유의사항
A38: 1) M/M 단가는 KOSA 2025년 적용 평균임금에 2026년 인상률(4.7%)을 적용한 추정치이며, 착수 시점 공표치로 갱신 필요
A39: 2) STT 엔진(30)·전문가 자문(8)은 가정치로 업체 견적 확인 필요. DRM·SSO는 27예산 금액(VAT포함)의 공급가 기준
A40: 3) 업무지원 Agent(200)·전자결재 연계(60)는 기획안 로드맵상 3단계('28년)로 본 견적에서 제외하고 그 재원을 기획안 신규 과업에 재배분
A41: 4) 대국민 챗봇(과제3) 운영을 위한 외부망(DMZ)·웹방화벽 등 H/W·보안 인프라는 27 H/W 예산(476, 내부망 기준)에 없어 별도 검토 필요

Sheet 1.과제-과업 매칭
A1: ① 과제-과업 정리 및 ② 27년 예산 매칭
A2: 매칭구분: ● 일치(27예산 반영) / ◐ 부분일치(범위 확대·구체화 필요) / ★ 기획안에만 있음(신규) / ▲ 27예산에만 있음(기획안 3단계)
A4: 과제 | B4: 과제명 | C4: 과업ID | D4: 과업명 | E4: 고도화 기획안 근거 | F4: 대응 27예산 SW항목 | G4: 27예산 비고상 대응내용 | H4: 매칭구분
A5: 과제1 | B5: 가스안전 지식DB 고도화 (데이터 정비) | C5: 1-1 | D5: 비정형 지식자산 전수조사 및 데이터 컨설팅 | E5: 부서·개인 보유 비정형 자료 전수조사, 수집→분류→정제→표준화→검증→최신화 절차 수립 | F5: - | G5: - | H5: ★ 기획안에만 있음
C6: 1-2 | D6: 법령·KGS Code·규정·매뉴얼·FAQ 데이터 정비 | E6: 법령·KGS Code·규정·매뉴얼·FAQ 등 데이터 정비 | F6: RAG 데이터 구축 및 고도화 | G6: 내부 문서 수집·전처리 체계 고도화 | H6: ● 일치
C7: 1-3 | D7: 데이터 표준화 및 메타데이터 구축 | E7: 데이터 표준화 및 메타데이터 구축 | F7: RAG 데이터 구축 및 고도화 | G7: 메타데이터 및 벡터DB 관리 고도화 | H7: ● 일치
C8: 1-4 | D8: 자료 최신화 및 버전관리 체계 구축 | E8: 자료 최신화 및 버전관리 체계 구축 | F8: 데이터 관리 및 운영 기능 | G8: 데이터 갱신 및 운영 기능 강화 (사업개요: 법령·사규·코드 자동 업로드) | H8: ● 일치
C9: 1-5 | D9: 지식DB 관리자 기능 개선 | E9: 지식DB 관리자 기능 개선 | F9: 데이터 관리 및 운영 기능 | G9: 관리자 기능 고도화 / 관리자 기반 RAG 데이터 관리 기능 고도화 | H9: ● 일치
C10: 1-6 | D10: 1차 사업 제외자료 확대 적재 | E10: 1차 사업 제외자료 확대 (고도화 추진방향) | F10: - | G10: - | H10: ★ 기획안에만 있음
C11: 1-7 | D11: 개인정보·민감정보 필터링 | E11: (기획안 KPI: 개인정보 침해 0건, 내부정보 외부노출 0건) | F11: 데이터 관리 및 운영 기능 | G11: 개인정보 및 민감정보 필터링 적용 | H11: ◐ 부분일치(범위확대)
A12: 과제2 | B12: 스마트온 2.0 연계를 통한 모바일 서비스 제공 | C12: 2-1 | D12: 스마트온 2.0 연계 | E12: 스마트온 2.0 연계 (검사지원처 협업) | F12: 모바일 서비스 구축 | G12: 기존 서비스 기반 모바일 환경 확장 | H12: ◐ 부분일치(범위확대)
C13: 2-2 | D13: 계정·인증 연계 | E13: 스마트온 2.0 계정·인증 연계 | F13: sso 인증서버소프트웨어 | G13: 기존 어드바이저 통합인증(로그인) 적용 | H13: ◐ 부분일치(범위확대)
C14: 2-3 | D14: 모바일 UI/UX 개발 | E14: 모바일 UI/UX 개발 | F14: 모바일 서비스 구축 | G14: 하이브리드 UI/UX 고도화 | H14: ● 일치
C15: 2-4 | D15: 모바일 검색 및 답변 근거 확인 | E15: 모바일 검색 및 답변 근거 확인 | F15: 모바일 서비스 구축 | G15: 질의응답 및 조회 기능 모바일 최적화 | H15: ● 일치
C16: 2-5 | D16: 음성입력(STT) | E16: 음성입력(STT) 기능 | F16: - | G16: - | H16: ★ 기획안에만 있음
C17: 2-6 | D17: 현장 활용성 기능 개선 | E17: 현장 활용성을 고려한 기능 개선 / 향후 현장자료·첨부파일 활용 확대 | F17: - | G17: - | H17: ★ 기획안에만 있음
A18: 과제3 | B18: 사이버지사 VOC 질의 챗봇 구축 (대국민 서비스) | C18: 3-1 | D18: 사이버지사 AI 상담챗봇 구축 | E18: 사이버지사 AI 상담챗봇 구축, 24시간 일반 상담 | F18: - | G18: - | H18: ★ 기획안에만 있음
C19: 3-2 | D19: 공개자료 기반 별도 지식DB 구축 | E19: 공개자료 기반 별도 지식DB, 내부자료와 대외자료 분리 | F19: - | G19: - | H19: ★ 기획안에만 있음
C20: 3-3 | D20: AI 상담체계(단계별 응대) 구현 | E20: 단순→AI 자동응답 / 전문→근거포함 답변 / 복합→담당부서 이관 | F20: - | G20: - | H20: ★ 기획안에만 있음
C21: 3-4 | D21: 담당부서 이관체계 및 VOC 연계 | E21: 복잡한 질의 담당부서 이관, VOC 연계 | F21: 업무지원 및 Agent 기능 | G21: 기존 VOC 분류 기능 고도화 (내부 VOC 대상) | H21: ◐ 부분일치(범위확대)
C22: 3-5 | D22: 대국민 서비스 보안·가드레일 | E22: (핵심원칙) 공개자료만 활용, 내부자료 원천배제 | F22: - | G22: - | H22: ★ 기획안에만 있음
C23: 3-6 | D23: 상담 운영 모니터링 | E23: (KPI) 챗봇 이용건수, 자동응답률, 이관률, 국민 만족도 | F23: - | G23: - | H23: ★ 기획안에만 있음
A24: 과제4 | B24: "정확도"를 넘어 "신뢰성" 확보 (AI 신뢰성 고도화) | C24: 4-1 | D24: RAG 검색체계·검색 알고리즘 고도화 | E24: RAG 검색체계 개선, 검색 알고리즘 고도화 | F24: RAG 데이터 구축 및 고도화 | G24: 검색 정확도 향상(Reranking) | H24: ● 일치
C25: 4-2 | D25: 문서 전처리·청킹 개선 | E25: 문서 전처리·청킹 개선 | F25: RAG 데이터 구축 및 고도화 | G25: 검색 정확도 향상(Chunking) | H25: ● 일치
C26: 4-3 | D26: 답변 근거자료 제시 | E26: 답변 근거자료 제시 | F26: 답변 품질 향상 | G26: 출처 기반 답변 및 근거 제시 고도화 | H26: ● 일치
C27: 4-4 | D27: 할루시네이션 및 치명적 오답 관리 | E27: 할루시네이션 및 치명적 오답 관리 | F27: 답변 품질 향상 | G27: Prompt 최적화 및 응답 정확도 개선, 답변 일관성 확보 | H27: ● 일치
C28: 4-5 | D28: 가스안전 전문 평가셋 구축 | E28: 가스안전 전문 평가셋 구축 | F28: - | G28: - | H28: ★ 기획안에만 있음
C29: 4-6 | D29: 정기 성능평가 체계 구축 | E29: 정기 성능평가 체계 구축 (정확성·근거성·최신성·안전성·완전성) | F29: - | G29: - | H29: ★ 기획안에만 있음
C30: 4-7 | D30: 사용자 피드백 및 오류관리 | E30: 사용자 피드백 및 오류관리 | F30: 답변 품질 향상 | G30: 품질 개선 | H30: ◐ 부분일치(범위확대)
A31: 공통 | B31: 사업관리 및 품질보증 | C31: 0-1 | D31: 사업관리·품질보증 | E31: (정보화사업 공통) 착수~종료 관리, 보안성 검토 대응 | F31: - | G31: - | H31: 공통
A32: (참고) | B32: 업무지원 Agent·전자결재 연계 (27예산 반영, 기획안 3단계 '28년) | C32: 5-1 | D32: 기존 VOC 분류 기능 고도화 | E32: 기획안 3단계(AI 에이전트) — 단, 일부는 과제3-4 VOC 연계에 활용 | F32: 업무지원 및 Agent 기능 | G32: 기존 VOC 분류 기능 고도화, 보고서 초안 생성 기능 확장, 규정/코드 기반 분석 지원 기능 강화(자동화 및 RPA 기능 제외) | H32: ▲ 27예산에만 있음
C33: 5-2 | D33: 보고서 초안 생성 기능 확장 | E33: 기획안 3단계(AI 에이전트, '28년) | F33: 업무지원 및 Agent 기능 | G33: 기존 VOC 분류 기능 고도화, 보고서 초안 생성 기능 확장, 규정/코드 기반 분석 지원 기능 강화(자동화 및 RPA 기능 제외) | H33: ▲ 27예산에만 있음
C34: 5-3 | D34: 규정/코드 기반 분석 지원 기능 강화 | E34: 기획안 3단계(AI 에이전트, '28년) | F34: 업무지원 및 Agent 기능 | G34: 기존 VOC 분류 기능 고도화, 보고서 초안 생성 기능 확장, 규정/코드 기반 분석 지원 기능 강화(자동화 및 RPA 기능 제외) | H34: ▲ 27예산에만 있음
C35: 5-4 | D35: 전자결재 시스템 연계 인터페이스 구현 | E35: 기획안 3단계(전자결재 연동, '28년) | F35: 전자결재 연계 (API 기반) | G35: 전자결재 시스템 연계 인터페이스 구현, 결재 문서 초안 생성 기능 제공(시스템 커스터마이징 제외) | H35: ▲ 27예산에만 있음
C36: 5-5 | D36: 결재 문서 초안 생성 기능 | E36: 기획안 3단계(전자결재 연동, '28년) | F36: 전자결재 연계 (API 기반) | G36: 전자결재 시스템 연계 인터페이스 구현, 결재 문서 초안 생성 기능 제공(시스템 커스터마이징 제외) | H36: ▲ 27예산에만 있음
A38: 매칭 요약
B39: 구분 | C39: 과업 수
B40: ● 일치 | C40: =COUNTIF($H$5:$H$36,B40) -> 10
B41: ◐ 부분일치(범위확대) | C41: =COUNTIF($H$5:$H$36,B41) -> 5
B42: ★ 기획안에만 있음 | C42: =COUNTIF($H$5:$H$36,B42) -> 11
...

Sheet 2.SW 구성
A1: ③ 고도화 기획안에 맞는 SW 표시
A2: 27예산 SW 8개 항목의 기획안 부합 여부 + 기획안 수행에 추가로 필요한 SW(상용/오픈소스)
A4: A. 27년 SW 예산 항목별 고도화 기획안 부합 여부
A5: No | B5: 27예산 SW 항목 | C5: 27예산(백만원) | D5: 기획안 부합 | E5: 대응 기획안 과제·과업 | F5: 판단 근거/조치
A6: 1 | B6: 모바일 서비스 구축 | C6: 60 | D6: ● 부합 | E6: 과제2 (2-1,2-3,2-4) | F6: 모바일 UI/UX·조회 최적화는 일치. 기획안은 "스마트온 2.0 연계"로 구체화 → 연계 범위 명시 필요
A7: 2 | B7: RAG 데이터 구축 및 고도화 | C7: 180 | D7: ● 부합 | E7: 과제1 (1-2,1-3,1-5), 과제4 (4-1,4-2) | F7: 수집·전처리·메타데이터·청킹·리랭킹 모두 기획안 과제1·4와 일치
A8: 3 | B8: 답변 품질 향상 | C8: 100 | D8: ● 부합 | E8: 과제4 (4-3,4-4,4-7) | F8: 근거제시·Prompt 최적화 일치. 기획안의 평가셋·정기 성능평가는 미포함 → 신규 반영
A9: 4 | B9: 업무지원 및 Agent 기능 | C9: 200 | D9: ▲ 미부합(3단계) | E9: 과제3-4 일부(VOC 분류) | F9: 기획안 로드맵상 AI 에이전트는 3단계('28년). VOC 분류 고도화만 대국민 VOC 이관에 활용, 나머지는 '28년 이연 권장
A10: 5 | B10: 전자결재 연계 (API 기반) | C10: 60 | D10: ▲ 미부합(3단계) | E10: - | F10: 기획안 로드맵상 전자결재 연동은 3단계('28년) → 27년 예산은 기획안 신규 과업으로 재배분 권장
A11: 6 | B11: 데이터 관리 및 운영 기능 | C11: 120 | D11: ● 부합 | E11: 과제1 (1-4,1-5,1-7) | F11: 최신화·버전관리·관리자 기능·민감정보 필터링 일치
A12: 7 | B12: DRM 보안소프트웨어 | C12: 16 | D12: ● 부합 | E12: 과제1-2, 과제3-2 | F12: 내부 DRM 문서 수집 시 복호화 필수, 대국민 DB 분리 시 반출통제
A13: 8 | B13: sso 인증서버소프트웨어 | C13: 22 | D13: ◐ 부분 부합 | E13: 과제2-2 | F13: 27예산은 "기존 어드바이저 로그인" 범위 → 스마트온 2.0 계정·인증 연계까지 확대 필요
B14: 합계 | C14: =SUM(C6:C13) -> 758 | D14: 부합 합계 | E14: =SUMIF(D6:D13,"●*",C6:C13)+SUMIF(D6:D13,"◐*",C6:C13) -> 498 | F14: ← 기획안 부합(●+◐) 금액 / 나머지는 3단계 이연 대상
A16: B. 고도화 기획안 수행에 필요한 SW(솔루션) 구성
A17: No | B17: SW(솔루션) | C17: 도입 방식 | D17: 기획안 필요성 | E17: 관련 과업 | F17: 27예산 반영 / 비고
A18: 1 | B18: DRM 보안소프트웨어 | C18: 상용 구매 | D18: ● 필수 | E18: 1-2, 3-2 | F18: 반영(16백만원). 내부 DRM 문서 수집·복호화
A19: 2 | B19: SSO 인증서버소프트웨어 | C19: 상용 구매 | D19: ● 필수 | E19: 2-2 | F19: 반영(22백만원). 스마트온 2.0 계정연계 지원 여부 확인
A20: 3 | B20: STT(음성인식) 엔진 | C20: 상용 구매(설치형) | D20: ★ 신규 필요 | E20: 2-5 | F20: 미반영 → 견적 30백만원(가정) 신규 반영
A21: 4 | B21: 대국민 웹 챗봇(UI 위젯) | C21: 개발 | D21: ★ 신규 필요 | E21: 3-1, 3-3 | F21: 미반영 → 인건비로 개발 반영(별도 챗봇 솔루션 구매 불요)
A22: 5 | B22: 개인정보·민감정보 탐지/마스킹 | C22: 개발(공통모듈) | D22: ● 필요 | E22: 1-7, 3-5 | F22: 27 데이터관리 항목에 기능개발로 반영. 상용 도입 시 별도 산정
A23: 6 | B23: 문서 파싱(HWP/PDF/표) 엔진 | C23: 오픈소스/기존 활용 | D23: ◐ 권장 | E23: 1-2 | F23: 1차 구축 파서 고도화. 스캔문서 비중 높을 경우 OCR 상용 검토
A24: 7 | B24: Reranker·하이브리드 검색 | C24: 오픈소스 | D24: ● 필요 | E24: 4-1 | F24: 라이선스 비용 없음(1차 구축 벡터DB 활용)
A25: 8 | B25: RAG 평가 도구 | C25: 오픈소스 | D25: ★ 신규 필요 | E25: 4-5, 4-6 | F25: 라이선스 비용 없음(평가 파이프라인 개발비에 포함)
A26: 9 | B26: 외부망(DMZ) 서비스 인프라·웹방화벽 | C26: H/W·보안 장비 | D26: ★ 신규 검토 | E26: 과제3 | F26: 27 H/W(476)는 내부망 기준 → 대국민 서비스용 망분리 인프라 별도 검토 필요(본 SW 견적 제외)
A27: 10 | B27: Agent 프레임워크 / 전자결재 연계 모듈 | C27: 개발 | D27: ▲ 기획안 3단계 | E27: - | F27: 27예산 반영(260)이나 기획안상 '28년 → 27년 범위 제외

Sheet 3.견적서
A1: ④ 과업 및 세부기능별 예산 견적서
A2: 단위: 백만원 / 인건비 = 투입M/M × M/M단가(0.개요 시트) / SW구매·직접경비 = 수량 × 단가(파란색 입력값)
A4: 과제 | B4: 과업ID | C4: 과업명 | D4: 세부기능 | E4: 매칭구분 | F4: 비목 | G4: 수량 | H4: 단위 | I4: 단가 | J4: 금액(VAT별도) | K4: 27예산 대응항목 | L4: 산출근거/비고
A5: 과제1 | C5: 가스안전 지식DB 고도화 (데이터 정비) | G5: =SUMIFS(G6:G18,F6:F18,"인건비") -> 10 | H5: M/M | J5: =SUM(J6:J18) -> 197.69895
A6: 과제1 | B6: 1-1 | C6: 비정형 지식자산 전수조사 및 데이터 컨설팅 | D6: 부서·개인 보유 자료 현황조사 및 자료목록(인벤토리) 작성 | E6: ★ 기획안에만 있음 | F6: 인건비 | G6: 1 | H6: M/M | I6: ='0.개요'!$B$13 -> 18.319895 | J6: =G6*I6 -> 18.319895 | K6: 신규(기획안에만 있음) | L6: 전 부서 대상 설문·인터뷰, 자료 유형/보안등급 분류
A7: 과제1 | B7: 1-1 | C7: 비정형 지식자산 전수조사 및 데이터 컨설팅 | D7: 지식자산 분류체계 및 데이터 정비 절차(수집~최신화) 수립 | E7: ★ 기획안에만 있음 | F7: 인건비 | G7: 1 | H7: M/M | I7: ='0.개요'!$B$13 -> 18.319895 | J7: =G7*I7 -> 18.319895 | K7: 신규(기획안에만 있음) | L7: 데이터 컨설팅 산출물: 분류체계·정비 가이드
A8: 과제1 | B8: 1-2 | C8: 법령·KGS Code·규정·매뉴얼·FAQ 데이터 정비 | D8: 문서 수집·변환 파이프라인 고도화(HWP/PDF/표·이미지 파싱) | E8: ● 일치 | F8: 인건비 | G8: 1 | H8: M/M | I8: ='0.개요'!$B$13 -> 18.319895 | J8: =G8*I8 -> 18.319895 | K8: RAG 데이터 구축 및 고도화 | L8: DRM 문서 복호화 연동 포함
A9: 과제1 | B9: 1-2 | C9: 법령·KGS Code·규정·매뉴얼·FAQ 데이터 정비 | D9: 데이터 정제·전처리(중복·오류 제거, 구조화) | E9: ● 일치 | F9: 인건비 | G9: 1.5 | H9: M/M | I9: ='0.개요'!$B$13 -> 18.319895 | J9: =G9*I9 -> 27.479842 | K9: RAG 데이터 구축 및 고도화
A10: 과제1 | B10: 1-2 | C10: 법령·KGS Code·규정·매뉴얼·FAQ 데이터 정비 | D10: DRM 보안소프트웨어(파일 복·암호화) 1식 | E10: ● 일치 | F10: SW구매 | G10: 1 | H10: 식 | I10: 14.5 | J10: =G10*I10 -> 14.5 | K10: DRM 보안소프트웨어 | L10: 27예산 16백만원(VAT포함) → 공급가 14.5 적용
A11: 과제1 | B11: 1-3 | C11: 데이터 표준화 및 메타데이터 구축 | D11: 데이터 표준 및 메타데이터 스키마 설계 | E11: ● 일치 | F11: 인건비 | G11: 0.5 | H11: M/M | I11: ='0.개요'!$B$13 -> 18.319895 | J11: =G11*I11 -> 9.1599473 | K11: RAG 데이터 구축 및 고도화 | L11: 문서유형·시행일·개정이력·보안등급 등
A12: 과제1 | B12: 1-3 | C12: 데이터 표준화 및 메타데이터 구축 | D12: 메타데이터 태깅 및 벡터DB 재적재·관리 기능 | E12: ● 일치 | F12: 인건비 | G12: 1.5 | H12: M/M | I12: ='0.개요'!$B$13 -> 18.319895 | J12: =G12*I12 -> 27.479842 | K12: RAG 데이터 구축 및 고도화
A13: 과제1 | B13: 1-4 | C13: 자료 최신화 및 버전관리 체계 구축 | D13: 법령·KGS Code·사규 변경분 자동 수집·업로드 | E13: ● 일치 | F13: 인건비 | G13: 1 | H13: M/M | I13: ='0.개요'!$B$13 -> 18.319895 | J13: =G13*I13 -> 18.319895 | K13: 데이터 관리 및 운영 기능 | L13: 27 사업내용 "자동 업로드 시스템" 대응
A14: 과제1 | B14: 1-4 | C14: 자료 최신화 및 버전관리 체계 구축 | D14: 문서 버전·이력 관리 및 폐지자료 자동 제외 | E14: ● 일치 | F14: 인건비 | G14: 0.5 | H14: M/M | I14: ='0.개요'!$B$13 -> 18.319895 | J14: =G14*I14 -> 9.1599473 | K14: 데이터 관리 및 운영 기능 | L14: 현행자료 반영률 KPI(≥98%) 대응
A15: 과제1 | B15: 1-5 | C15: 지식DB 관리자 기능 개선 | D15: 문서 등록·검수·승인 워크플로 | E15: ● 일치 | F15: 인건비 | G15: 0.5 | H15: M/M | I15: ='0.개요'!$B$13 -> 18.319895 | J15: =G15*I15 -> 9.1599473 | K15: 데이터 관리 및 운영 기능
A16: 과제1 | B16: 1-5 | C16: 지식DB 관리자 기능 개선 | D16: 지식DB 품질 모니터링 화면(적재현황·오류·최신성) | E16: ● 일치 | F16: 인건비 | G16: 0.5 | H16: M/M | I16: ='0.개요'!$B$13 -> 18.319895 | J16: =G16*I16 -> 9.1599473 | K16: RAG 데이터 구축 및 고도화
A17: 과제1 | B17: 1-6 | C17: 1차 사업 제외자료 확대 적재 | D17: 1차 제외자료 선별·정비·적재 | E17: ★ 기획안에만 있음 | F17: 인건비 | G17: 0.5 | H17: M/M | I17: ='0.개요'!$B$13 -> 18.319895 | J17: =G17*I17 -> 9.1599473 | K17: 신규(기획안에만 있음)
A18: 과제1 | B18: 1-7 | C18: 개인정보·민감정보 필터링 | D18: 개인정보·민감정보 탐지 및 마스킹(적재·답변 단계) | E18: ◐ 부분일치(범위확대) | F18: 인건비 | G18: 0.5 | H18: M/M | I18: ='0.개요'!$B$13 -> 18.319895 | J18: =G18*I18 -> 9.1599473 | K18: 데이터 관리 및 운영 기능 | L18: 과제3 대국민 입력필터와 공통 모듈화
A19: 과제2 | C19: 스마트온 2.0 연계를 통한 모바일 서비스 제공 | G19: =SUMIFS(G20:G30,F20:F30,"인건비") -> 5.5 | H19: M/M | J19: =SUM(J20:J30) -> 150.75942
A20: 과제2 | B20: 2-1 | C20: 스마트온 2.0 연계 | D20: 스마트온 2.0 연계 인터페이스(API/웹뷰) 개발 | E20: ◐ 부분일치(범위확대) | F20: 인건비 | G20: 1 | H20: M/M | I20: ='0.개요'!$B$13 -> 18.319895 | J20: =G20*I20 -> 18.319895 | K20: 모바일 서비스 구축 | L20: 27예산은 "모바일 환경 확장"만 명시 → 스마트온 연계로 범위 구체화
A21: 과제2 | B21: 2-2 | C21: 계정·인증 연계 | D21: SSO 연동 및 스마트온 계정 매핑 | E21: ◐ 부분일치(범위확대) | F21: 인건비 | G21: 0.5 | H21: M/M | I21: ='0.개요'!$B$13 -> 18.319895 | J21: =G21*I21 -> 9.1599473 | K21: sso 인증서버소프트웨어
A22: 과제2 | B22: 2-2 | C22: 계정·인증 연계 | D22: SSO 인증서버소프트웨어 1식 | E22: ◐ 부분일치(범위확대) | F22: SW구매 | G22: 1 | H22: 식 | I22: 20 | J22: =G22*I22 -> 20 | K22: sso 인증서버소프트웨어 | L22: 27예산 22백만원(VAT포함) → 공급가 20.0 적용. 스마트온 계정연계 지원 여부 확인 필요
A23: 과제2 | B23: 2-3 | C23: 모바일 UI/UX 개발 | D23: 현장 검사원용 모바일 화면 설계(UI/UX) | E23: ● 일치 | F23: 인건비 | G23: 0.5 | H23: M/M | I23: ='0.개요'!$B$13 -> 18.319895 | J23: =G23*I23 -> 9.1599473 | K23: 모바일 서비스 구축
A24: 과제2 | B24: 2-3 | C24: 모바일 UI/UX 개발 | D24: 하이브리드(반응형) 모바일 UI 구현 | E24: ● 일치 | F24: 인건비 | G24: 1 | H24: M/M | I24: ='0.개요'!$B$13 -> 18.319895 | J24: =G24*I24 -> 18.319895 | K24: 모바일 서비스 구축
A25: 과제2 | B25: 2-4 | C25: 모바일 검색 및 답변 근거 확인 | D25: 질의응답·조회 기능 모바일 최적화 | E25: ● 일치 | F25: 인건비 | G25: 0.5 | H25: M/M | I25: ='0.개요'!$B$13 -> 18.319895 | J25: =G25*I25 -> 9.1599473 | K25: 모바일 서비스 구축
A26: 과제2 | B26: 2-4 | C26: 모바일 검색 및 답변 근거 확인 | D26: 모바일 근거문서(KGS Code 조항) 뷰어 | E26: ● 일치 | F26: 인건비 | G26: 0.5 | H26: M/M | I26: ='0.개요'!$B$13 -> 18.319895 | J26: =G26*I26 -> 9.1599473 | K26: 모바일 서비스 구축 | L26: 현장활용 예: 기준검색→Code제시→근거제공→문서연결
A27: 과제2 | B27: 2-5 | C27: 음성입력(STT) | D27: STT 엔진 연동 및 음성질의 처리 | E27: ★ 기획안에만 있음 | F27: 인건비 | G27: 0.5 | H27: M/M | I27: ='0.개요'!$B$13 -> 18.319895 | J27: =G27*I27 -> 9.1599473 | K27: 신규(기획안에만 있음)
A28: 과제2 | B28: 2-5 | C28: 음성입력(STT) | D28: 가스안전 전문용어 사전 구축·인식률 튜닝 | E28: ★ 기획안에만 있음 | F28: 인건비 | G28: 0.5 | H28: M/M | I28: ='0.개요'!$B$13 -> 18.319895 | J28: =G28*I28 -> 9.1599473 | K28: 신규(기획안에만 있음)
A29: 과제2 | B29: 2-5 | C29: 음성입력(STT) | D29: STT 엔진 소프트웨어 1식(온프레미스) | E29: ★ 기획안에만 있음 | F29: SW구매 | G29: 1 | H29: 식 | I29: 30 | J29: =G29*I29 -> 30 | K29: 신규(기획안에만 있음) | L29: 가정치 — 업체 견적 확인 필요(폐쇄망 설치형 기준)
A30: 과제2 | B30: 2-6 | C30: 현장 활용성 기능 개선 | D30: 현장 사진·첨부파일 첨부 질의(기초기능) | E30: ★ 기획안에만 있음 | F30: 인건비 | G30: 0.5 | H30: M/M | I30: ='0.개요'!$B$13 -> 18.319895 | J30: =G30*I30 -> 9.1599473 | K30: 신규(기획안에만 있음) | L30: 기획안상 "향후" 과제 — 27년 기초기능만 반영
A31: 과제3 | C31: 사이버지사 VOC 질의 챗봇 구축 (대국민 서비스) | G31: =SUMIFS(G32:G42,F32:F42,"인건비") -> 7.5 | H31: M/M | J31: =SUM(J32:J42) -> 137.39921
A32: 과제3 | B32: 3-1 | C32: 사이버지사 AI 상담챗봇 구축 | D32: 대국민 웹 챗봇 UI(위젯) 개발 | E32: ★ 기획안에만 있음 | F32: 인건비 | G32: 1 | H32: M/M | I32: ='0.개요'!$B$13 -> 18.319895 | J32: =G32*I32 -> 18.319895 | K32: 신규(기획안에만 있음) | L32: 웹접근성 인증 기준 준수
A33: 과제3 | B33: 3-1 | C33: 사이버지사 AI 상담챗봇 구축 | D33: 사이버지사 홈페이지 연동 | E33: ★ 기획안에만 있음 | F33: 인건비 | G33: 0.5 | H33: M/M | I33: ='0.개요'!$B$13 -> 18.319895 | J33: =G33*I33 -> 9.1599473 | K33: 신규(기획안에만 있음) | L33: 홍보소통실 협업
A34: 과제3 | B34: 3-2 | C34: 공개자료 기반 별도 지식DB 구축 | D34: 공개 가능자료(법령·KGS Code 등) 선별·적재 | E34: ★ 기획안에만 있음 | F34: 인건비 | G34: 1 | H34: M/M | I34: ='0.개요'!$B$13 -> 18.319895 | J34: =G34*I34 -> 18.319895 | K34: 신규(기획안에만 있음) | L34: 사규·인사·개인정보 원천 배제
A35: 과제3 | B35: 3-2 | C35: 공개자료 기반 별도 지식DB 구축 | D35: 내부/대외 지식DB 분리(별도 인덱스·접근통제) | E35: ★ 기획안에만 있음 | F35: 인건비 | G35: 0.5 | H35: M/M | I35: ='0.개요'!$B$13 -> 18.319895 | J35: =G35*I35 -> 9.1599473 | K35: 신규(기획안에만 있음)
A36: 과제3 | B36: 3-3 | C36: AI 상담체계(단계별 응대) 구현 | D36: 질의 유형 분류 및 3단계 라우팅 | E36: ★ 기획안에만 있음 | F36: 인건비 | G36: 1 | H36: M/M | I36: ='0.개요'!$B$13 -> 18.319895 | J36: =G36*I36 -> 18.319895 | K36: 신규(기획안에만 있음)
A37: 과제3 | B37: 3-3 | C37: AI 상담체계(단계별 응대) 구현 | D37: 근거자료 포함 대국민 답변 생성 | E37: ★ 기획안에만 있음 | F37: 인건비 | G37: 0.5 | H37: M/M | I37: ='0.개요'!$B$13 -> 18.319895 | J37: =G37*I37 -> 9.1599473 | K37: 신규(기획안에만 있음)
A38: 과제3 | B38: 3-4 | C38: 담당부서 이관체계 및 VOC 연계 | D38: 전문상담 담당부서 이관 워크플로 | E38: ◐ 부분일치(범위확대) | F38: 인건비 | G38: 0.5 | H38: M/M | I38: ='0.개요'!$B$13 -> 18.319895 | J38: =G38*I38 -> 9.1599473 | K38: 신규(기획안에만 있음)
A39: 과제3 | B39: 3-4 | C39: 담당부서 이관체계 및 VOC 연계 | D39: VOC 시스템 연계 및 기존 VOC 분류모델 재활용 | E39: ◐ 부분일치(범위확대) | F39: 인건비 | G39: 1 | H39: M/M | I39: ='0.개요'!$B$13 -> 18.319895 | J39: =G39*I39 -> 18.319895 | K39: 업무지원 및 Agent 기능 | L39: 27 Agent 항목 "VOC 분류 고도화"를 대국민 이관에 활용
A40: 과제3 | B40: 3-5 | C40: 대국민 서비스 보안·가드레일 | D40: 입력 필터(개인정보·비속어·프롬프트 인젝션) | E40: ★ 기획안에만 있음 | F40: 인건비 | G40: 0.5 | H40: M/M | I40: ='0.개요'!$B$13 -> 18.319895 | J40: =G40*I40 -> 9.1599473 | K40: 신규(기획안에만 있음)
A41: 과제3 | B41: 3-5 | C41: 대국민 서비스 보안·가드레일 | D41: 답변 범위 제한 및 면책·이관 안내 | E41: ★ 기획안에만 있음 | F41: 인건비 | G41: 0.5 | H41: M/M | I41: ='0.개요'!$B$13 -> 18.319895 | J41: =G41*I41 -> 9.1599473 | K41: 신규(기획안에만 있음)
...

Sheet 4.27예산 대비
A1: 27년 SW 예산 항목 ↔ 고도화 견적 대비표
A2: 단위: 백만원(VAT포함). 견적액은 3.견적서의 "27예산 대응항목"별 합계 × (1+VAT)
A4: 27예산 SW 항목 | B4: 27예산 | C4: 고도화 견적 | D4: 증감(견적−예산) | E4: 조치
A5: 모바일 서비스 구축 | B5: 60 | C5: =SUMIFS('3.견적서'!$J$5:$J$57,'3.견적서'!$K$5:$K$57,A5)*(1+'0.개요'!$B$10) -> 70.531595 | D5: =C5-B5 -> 10.531595 | E5: 스마트온 2.0 연계로 구체화(STT는 신규 항목으로 별도)
A6: RAG 데이터 구축 및 고도화 | B6: 180 | C6: =SUMIFS('3.견적서'!$J$5:$J$57,'3.견적서'!$K$5:$K$57,A6)*(1+'0.개요'!$B$10) -> 141.06319 | D6: =C6-B6 -> -38.936811 | E6: 유지
A7: 답변 품질 향상 | B7: 100 | C7: =SUMIFS('3.견적서'!$J$5:$J$57,'3.견적서'!$K$5:$K$57,A7)*(1+'0.개요'!$B$10) -> 60.455652 | D7: =C7-B7 -> -39.544348 | E7: 유지(평가셋·정기평가는 신규 항목)
A8: 업무지원 및 Agent 기능 | B8: 200 | C8: =SUMIFS('3.견적서'!$J$5:$J$57,'3.견적서'!$K$5:$K$57,A8)*(1+'0.개요'!$B$10) -> 20.151884 | D8: =C8-B8 -> -179.84812 | E8: VOC 분류 재활용분만 반영, 보고서·규정분석 Agent는 '28년(3단계) 이연
A9: 전자결재 연계 (API 기반) | B9: 60 | C9: =SUMIFS('3.견적서'!$J$5:$J$57,'3.견적서'!$K$5:$K$57,A9)*(1+'0.개요'!$B$10) -> 0 | D9: =C9-B9 -> -60 | E9: '28년(3단계) 이연 → 기획안 신규 과업 재원으로 전환
A10: 데이터 관리 및 운영 기능 | B10: 120 | C10: =SUMIFS('3.견적서'!$J$5:$J$57,'3.견적서'!$K$5:$K$57,A10)*(1+'0.개요'!$B$10) -> 50.37971 | D10: =C10-B10 -> -69.62029 | E10: 유지
A11: DRM 보안소프트웨어 | B11: 16 | C11: =SUMIFS('3.견적서'!$J$5:$J$57,'3.견적서'!$K$5:$K$57,A11)*(1+'0.개요'!$B$10) -> 15.95 | D11: =C11-B11 -> -0.05 | E11: 유지
A12: sso 인증서버소프트웨어 | B12: 22 | C12: =SUMIFS('3.견적서'!$J$5:$J$57,'3.견적서'!$K$5:$K$57,A12)*(1+'0.개요'!$B$10) -> 32.075942 | D12: =C12-B12 -> 10.075942 | E12: 스마트온 계정연계까지 범위 확대
A13: 신규(기획안에만 있음) | B13: 0 | C13: =SUMIFS('3.견적서'!$J$5:$J$57,'3.견적서'!$K$5:$K$57,A13)*(1+'0.개요'!$B$10) -> 303.77449 | D13: =C13-B13 -> 303.77449 | E13: 기획안에만 있는 과업(전수조사·STT·대국민 챗봇·평가셋 등)
A14: 공통(사업관리·품질) | B14: 0 | C14: =SUMIFS('3.견적서'!$J$5:$J$57,'3.견적서'!$K$5:$K$57,A14)*(1+'0.개요'!$B$10) -> 60.455652 | D14: =C14-B14 -> 60.455652 | E14: 사업관리·통합테스트(27예산 각 항목에 내재되어 있던 공통비 명시)
A15: 합계 | B15: =SUM(B5:B14) -> 758 | C15: =SUM(C5:C14) -> 754.83812 | D15: =SUM(D5:D14) -> -3.1618808 | E15: =IF(ABS(C15-'3.견적서'!J65)<0.01,"검증OK: 견적서 총액과 일치","검증 오류: 견적서 총액과 불일치") -> 검증OK: 견적서 총액과 일치
