Workbook

Sheet 요구사항 매핑
A1: 「사내 엔지니어링 메타DB 구축 및 오픈소스 AI(SLM/LLM) 기반 온프레미스 RAG 시스템 개발」 — 과업 분해 및 제품 적합도(PMF) 분석
A2: 기준: 과업지시서 RFP-ENG-AI-2026-02(개정판, 2026.10) vs. Agent-X 기능 ID 대장 v3.2.1(486건, 2026-07-29) — 조회·판정 2026-10-19, 초안
A3: ★ = 주요 리스크 항목 (제안 전 반드시 확인 필요)
A4: 기능 ID = 기능명세서 시트 접두어 + 원본NO (LLM · LLMO=LLMOps · RAG=RAGOps · AGT=AgentOps · MLO=MLOps · GRAG=GraphRAG · RAGA=RAG Agent · NSQL=NL2SQL Agent) / RFP 항목의 ①②… = 해당 절의 글머리 순서
A5: 순번 | B5: 구분 | C5: RFP 항목 | D5: 과업 (세부 작업) | E5: 단계 | F5: 개발 여부 | G5: 근거 기능명세서 | H5: 기술 요소 | I5: 의견 | J5: 리스크
A6: 1 | B6: 사업관리 | C6: §5 · §6 | D6: 총괄 PM 지정, 주간/월간 공정 보고, 형상관리, TFT 합동 애자일 스프린트 운영 | E6: 전 단계 | F6: 신규 | G6: - | H6: 사내 Git(GitLab/Gitea)·이슈관리(Jira/Redmine) — 폐쇄망 설치 | I6: 수행 과업. 공동 설계 방식이라 TFT 도메인 검증자(공정·기계·계장 각 1명) 가용 시간이 일정 병목 — 스프린트별 검증 일정 확약 필요
A7: 2 | B7: 사업관리 | C7: §6 M1 | D7: 요구사항 정의서 작성, 5대 산출물 샘플 분석(산출물별 서식 유형·버전 수 조사) | E7: M1 | F7: 신규 | G7: - | H7: 서식 프로파일링 스크립트(Python·openpyxl) | I7: 프로젝트별 서식 편차가 파서 공수를 좌우 — M1에서 산출물별 서식 유형 수·샘플 건수를 확정해야 M2~M3 일정이 성립
A8: 3 | B8: 사업관리 | C8: §6 M1 · §4.3 | D8: GPU 서버·개발 환경 셋업(드라이버·CUDA·컨테이너 런타임), 폐쇄망 반입 패키지 구성(모델 가중치·wheel·이미지) | E8: M1 | F8: 솔루션에 포함 + 추가 개발 | G8: MLOps | H8: NVIDIA Driver·CUDA, Docker/단일 노드 K8s, 사내 이미지·PyPI 미러 | I8: 노드·GPU 자동 등록(MLO-045·049), GPU 정보 갱신(MLO-050). 오프라인 설치 패키지 반입은 수행 과업. 서버가 '도입 예정'이라 도입 지연 시 M1부터 밀림 | J8: ★
A9: 4 | B9: 사업관리 | C9: §5 · §6 M6 | D9: 시스템 기술 이전, 사용자/운영자 매뉴얼 작성, 관리자 교육 | E9: M6 | F9: 신규 | G9: - | H9: - | I9: 수행 과업
A10: 5 | B10: 사업관리 | C10: §6 M6 | D10: 시스템 소스코드 일체 제출 | E10: M6 | F10: 신규 | G10: - | H10: - | I10: 커스텀 개발분(파서·검증 엔진·포털·연계 모듈)은 제출 가능. Agent-X 제품 소스는 제출 대상이 아님 — 산출물을 '개발분 소스 + 제품 라이선스·설치본'으로 협의 필요 | J10: ★
A11: 6 | B11: 메타DB 설계 | C11: §2 · §3.1-① · §4.2 | D11: 5대 산출물 관계를 고려한 MSSQL 메타DB 스키마(ERD) 공동 설계 — 공통 마스터(Project·Unit·Equipment·Tag·Document·Revision) + 산출물별 상세 테이블 | E11: M1 | F11: 신규 | G11: - | H11: MSSQL 2019/2022, ERD 도구, DB 마이그레이션(Flyway/SSDT) | I11: 제품에 정형 메타DB 모델링 기능 없음. Tag No·Equipment No를 교차 키로 하는 공통 마스터 설계가 정합성 검증과 Text-to-SQL 정확도를 함께 결정
A12: 7 | B12: 메타DB 설계 | C12: §3.1-① · §3.2-③ | D12: 원천 근거 추적 컬럼 설계(파일 경로·시트명·행/셀 주소·리비전·적재 배치 ID) | E12: M1 | F12: 신규 | G12: - | H12: MSSQL 출처 컬럼, 파일서버 UNC 링크 | I12: 포털의 '근거 위치(시트명·행·파일 링크)' 표시를 위해 모든 적재 레코드에 출처 좌표를 보존해야 함 — 스키마 단계에서 확정
A13: 8 | B13: 메타DB 설계 | C13: §3.1-① · §3.2-④ | D13: 공학 단위·값 표준화 설계(값/단위 컬럼 분리, SI 환산 컬럼, Min/Normal/Max 분리, 'N/A'·'-'·결측 코드화) | E13: M1~M3 | F13: 신규 | G13: - | H13: pint(단위 변환), MSSQL 계산 컬럼 | I13: 'barg·kg/cm²G·psig', '°C·°F' 혼재 시 Text-to-SQL 비교 질의와 가드레일 수치 대조가 모두 틀어짐 — 단위 정규화는 정확도 전제 조건
A14: 9 | B14: 메타DB 설계 | C14: §3.1-③ | D14: 엔지니어링 용어·Tag 표기 사전(동의어·약어·'FT-1001'/'FT 1001' 표기 변형), 서비스명 정규화 | E14: M1~M3 | F14: 솔루션에 포함 + 추가 개발 | G14: GraphRAG | H14: 용어 사전 테이블(MSSQL), 정규식 Tag 파서 | I14: 사전 기반 추출·사전 등록 API(GRAG-005), 엔터티 통합(GRAG-006)으로 표기 변형 통합 가능. 공정·기계·계장 용어집 구축은 TFT 가이드 기반 수행
A15: 10 | B15: 파서 · ETL | C15: §2-1 · §3.1-② | D15: PDS 파서(Excel) — 다단 헤더·복합 표 해석, 운전/설계 조건(Normal/Rated/Max 유량, P&T, Density, Viscosity, 열량), 조성, 부식 여유, 특수 사양 추출 | E15: M2~M3 | F15: 신규 | G15: - | H15: pandas·openpyxl(병합셀 해제·헤더 경로 평탄화), 서식별 매핑 규칙(YAML) | I15: 제품 문서 변환(RAG-050)은 PDF 경유 텍스트화라 셀 좌표·다단 헤더 구조를 보존하지 못함 → 정형 추출은 전용 파서 신규. 프로젝트 서식 수에 비례해 공수 증가 | J15: ★
A16: 11 | B16: 파서 · ETL | C16: §2-1 · §3.1-② | D16: PDS 파서(PDF) — 비정형 다단·복합 표 처리, 스캔본 OCR | E16: M2~M3 | F16: 솔루션에 포함 + 추가 개발 | G16: RAG Agent · AgentOps | H16: PyMuPDF·pdfplumber/Camelot(텍스트 PDF), DOC-AI OCR(스캔), VLM 표 재판독 | I16: DOC-AI OCR(RAGA-011)·페이지 태그(RAGA-013)·표 왜곡 시 이미지 재판독(RAGA-014), 문서 추출 노드(AGT-019). 수치 셀 정확도 검증(범위·형식 검사)은 개발
A17: 12 | B17: 파서 · ETL | C17: §2-2 · §3.1-② | D17: MDS 파서 — Excel/Word 다단 헤더·병합셀, Tag No·설계 P/T·치수·용량·동력·모터 사양·재질(Shell/Tube/Impeller)·노즐 스케줄·플랜지 규격 | E17: M2~M3 | F17: 신규 | G17: - | H17: openpyxl, python-docx(표·병합셀), 장비 유형별(펌프·열교환기·용기·압축기) 템플릿 | I17: 장비 유형마다 데이터시트 서식이 달라 '유형 × 프로젝트' 조합별 매핑 필요. 노즐 스케줄은 1:N 하위 테이블로 분리
A18: 13 | B18: 파서 · ETL | C18: §2-3 · §3.1-② | D18: Instrument Index 파서 — 대용량 시트, Tag No·계기 유형·Service·Loop No·I/O(AI/AO/DI/DO)·설치 위치·P&ID 번호 | E18: M2 | F18: 신규 | G18: - | H18: pandas(청크 로딩), 헤더 동의어 매핑, pyodbc fast_executemany/BCP 대량 적재 | I18: 가장 정형적인 표라 선행 구현 권장(Tag 마스터 원천). ISA 5.1 기준 계기 유형 코드 표준화
A19: 14 | B19: 파서 · ETL | C19: §2-4 · §3.1-② | D19: Instrument Datasheet 파서 — Excel·Form PDF, Calibration Range·전원·출력 신호·연결 규격·방폭 등급·Body/Trim 재질·Cv·제조사 | E19: M2~M3 | F19: 솔루션에 포함 + 추가 개발 | G19: RAG Agent | H19: pypdf(AcroForm 필드 추출), openpyxl, DOC-AI OCR(스캔본) | I19: Form PDF는 폼 필드 직접 추출이 가장 정확. 필드가 평탄화된 PDF·스캔본은 OCR(RAGA-011)로 폴백 — 폼 필드 보존 비율을 샘플로 확인 필요
A20: 15 | B20: 파서 · ETL | C20: §2-5 · §3.1-② | D20: Lesson Learned 파서 — Excel/Word/Report 정형·비정형 혼재, 프로젝트·공종·발생 단계·이슈·Root Cause·재발 방지 조치 구조화 | E20: M2~M3 | F20: 솔루션에 포함 + 추가 개발 | G20: LLM · AgentOps · RAGOps | H20: python-docx, LLM 구조화 출력(JSON Schema), 구조 기반 청킹 | I20: 정형 시트는 직접 매핑, 서술형 리포트는 LLM 노드 구조화 출력(AGT-013)으로 필드 추출 후 검증자 확인. 본문은 청킹(RAG-062)으로 벡터 색인 병행
A21: 16 | B21: 파서 · ETL | C21: §3.1-② · §5 | D21: 데이터 적재 자동화(ETL) — 파일서버 감시·증분 적재·리비전 관리·재처리, Staging→Core 적재 | E21: M2~M3 | F21: 솔루션에 포함 + 추가 개발 | G21: RAGOps | H21: Python ETL 작업 + RAGOps 작업 등록·파이프라인·스케줄 엔진, SQLAlchemy/pyodbc | I21: 무코드 작업 등록(RAG-122)·커스텀 파이프라인(RAG-123)·cron 스케줄(RAG-126)·재시도(RAG-128)·실행 이력(RAG-131)을 오케스트레이션에 활용. RAGOps는 RAG 색인용 — MSSQL 적재 로직은 개발
A22: 17 | B22: 파서 · ETL | C22: §3.1-② · §6 M2~M3 | D22: 과거 프로젝트 데이터 대량 파싱 및 MSSQL 메타DB 적재 | E22: M2~M3 | F22: 신규 | G22: - | H22: 배치 실행, 적재 결과 리포트 | I22: 대상 프로젝트 수·파일 수·서식 종류가 RFP에 없음 — 적재 범위(건수·연도)를 계약 전 확정해야 공수 산정 가능 | J22: ★
A23: 18 | B23: 정합성 검증 | C23: §3.1-③ (1) | D23: PDS ↔ MDS 교차 검증 — 설계 압력/온도 ≥ 운전 Max + 여유, 유량·용량·동력 일치, 재질-부식 여유 적합성 | E23: M2~M3 | F23: 신규 | G23: GraphRAG | H23: 룰 엔진(Python + SQL 뷰), 룰 정의 테이블(버전 관리), 허용 오차 파라미터 | I23: 제품에 정형 데이터 교차 검증 엔진 없음. 업무 규칙 추출(GRAG-007)은 문서 속 규칙 후보 발굴에만 활용. 룰은 TFT(공정·기계)가 정의 — 룰 확정이 M2 이후면 일정 지연
A24: 19 | B24: 정합성 검증 | C24: §3.1-③ (2) | D24: Instrument Index ↔ Instrument Datasheet Tag 매핑 무결성(누락·중복·불일치) 검증 | E24: M2~M3 | F24: 신규 | G24: - | H24: SQL Anti-Join, 정규화 Tag 키 매칭, rapidfuzz 퍼지 매칭 | I24: Tag 표기 사전(순번 9) 위에서 수행. 키 매칭은 SQL로 충분
A25: 20 | B25: 정합성 검증 | C25: §3.1-③ (2) | D25: Instrument Index ↔ P&ID 도면 매핑 무결성 검증 | E25: M2~M3 | F25: 신규 | G25: - | H25: P&ID Tag 목록(SPPID/AVEVA 추출본) 또는 도면 PDF 텍스트 추출 | I25: P&ID는 5대 산출물에 없음 — P&ID Tag 원천(설계 툴 추출 리스트 vs 도면 PDF/CAD)이 RFP에 없음. 도면 OCR 기반 Tag 인식이면 별도 과업 규모 | J25: ★
A26: 21 | B26: 정합성 검증 | C26: §3.1-③ (3) | D26: Lesson Learned ↔ PDS/MDS 설계 파라미터 연계 태깅(키워드·설비 유형·Tag 기준 릴레이션 매핑) | E26: M3~M4 | F26: 솔루션에 포함 + 추가 개발 | G26: GraphRAG · LLM | H26: LLM 엔터티 추출, 매핑 테이블(LL_ID ↔ Equipment/Tag/Parameter), 그래프 DB(선택) | I26: 트리플 추출·신뢰도·출처(GRAG-004), 인과 관계(GRAG-008), 그래프 색인(GRAG-009)으로 설비-이슈-원인 관계 생성. MSSQL 매핑 테이블 역적재는 개발. 견적 구성 시 GraphRAG 포함 여부 결정 필요
A27: 22 | B27: 정합성 검증 | C27: §3.1-③ · §6 M2~M3 | D27: 정합성 검증 결과서(룰별 위반 건수·상세 목록) 생성 | E27: M3 | F27: 신규 | G27: - | H27: SQL 리포트, Excel 내보내기 | I27: 수행 과업
A28: 23 | B28: 파싱 예외 관리 | C28: §3.1-④ | D28: 파싱 실패·결측·형식 오류 실시간 로깅 및 오류 유형 분류 | E28: M2~M3 | F28: 솔루션에 포함 + 추가 개발 | G28: MLOps · RAGOps | H28: OpenTelemetry → ClickHouse 로그, 오류 테이블(MSSQL), 임계 알림 | I28: 로그 수집·검색(MLO-063~066), 임계 알림(MLO-075), 작업 실행 이력(RAG-131). 셀 단위 오류 레코드(파일·시트·셀·사유) 스키마는 개발
A29: 24 | B29: 파싱 예외 관리 | C29: §3.1-④ | D29: 도메인 검증자 전용 웹 예외 처리/수정 UI — 원본 셀 대조 화면, 값 수정·승인·반려, 수정 이력 | E29: M3~M5 | F29: 신규 | G29: - | H29: React/Vue + FastAPI, 원본 Excel 미리보기(SheetJS), 승인 워크플로 | I29: 제품 청크 편집(RAG-053~057)은 비정형 청크용 — 정형 레코드 검수 UI 없음. 화면 범위가 크므로 화면 목록을 M1에서 확정
A30: 25 | B30: 파싱 예외 관리 | C30: §5 | D30: 검증자 피드백 반영 파서 튜닝(서식 매핑 규칙 추가·재파싱) | E30: M3 | F30: 신규 | G30: - | H30: 매핑 규칙 설정 파일, 재처리 배치 | I30: 수행 과업 — 재파싱 시 사람이 수정한 값을 덮어쓰지 않는 우선순위 규칙 필요
A31: 26 | B31: AI 인프라 · 서빙 | C31: §3.2-① · §4.3 | D31: SLM/LLM 동시 구동 GPU 리소스 파티셔닝 방안 수립(L40S 48GB × 2) | E31: M1 · M4 | F31: 솔루션에 포함 + 추가 개발 | G31: MLOps · LLMOps | H31: vLLM(gpu-memory-utilization·Tensor Parallel), AWQ/GPTQ INT4 | I31: L40S는 MIG 미지원·NVLink 없음 → 프로세스 단위 VRAM 분할만 가능. 70B INT4(가중치 약 40GB)는 GPU 1장에 KV 캐시 여유가 거의 없어 TP=2 분산이 현실적(안은 '기술 요소 매핑' 시트). GPU 그룹·할당 추적(MLO-051·054), 자원 사양 지정 배포(MLO-028) | J31: ★
A32: 27 | B32: AI 인프라 · 서빙 | C32: §3.2-① | D32: 오픈소스 SLM 서빙(Qwen2.5-14B/32B, Llama-3.1-8B 등) | E32: M4 | F32: 솔루션에 포함 | G32: MLOps · LLMOps · LLM | H32: vLLM, safetensors 가중치(사내 반입), AWQ INT4 | I32: vLLM 지원 모델 탑재(LLM-002), 서비스 생성·버전 지정 배포(MLO-027·028), 로드/언로드(LLMO-011), 다중 모델 운영(LLMO-015)
A33: 28 | B33: AI 인프라 · 서빙 | C33: §3.2-① | D33: 양자화 LLM 서빙(Llama-3.1-70B 4bit 등) | E33: M4 | F33: 솔루션에 포함 + 추가 개발 | G33: MLOps · LLMOps | H33: vLLM TP=2, AWQ/GPTQ 4bit 체크포인트 | I33: 서빙 체계는 제품(MLO-028). 양자화 체크포인트 선정, 한국어 품질·처리량 실측은 수행. PCIe 기반 TP라 처리량 저하 — 동시 사용자 목표 확인 필요
A34: 29 | B34: AI 인프라 · 서빙 | C34: §3.2-① | D34: 모델 통합 게이트웨이(OpenAI 호환 API) 및 작업별 모델 라우팅(SQL 생성=SLM, 종합 답변=LLM) | E34: M4 | F34: 솔루션에 포함 | G34: MLOps · LLMOps | H34: 모델 게이트웨이(OpenAI 호환), config 기반 모델 등록 | I34: OpenAI 호환 API(MLO-042), 다중 백엔드·라우팅(MLO-043), 모델 비교(LLMO-031). 외부 상용 API 연동은 폐쇄망 원칙상 미등록
A35: 30 | B35: AI 인프라 · 서빙 | C35: §3.2-① | D35: TensorRT-LLM 기반 서빙 | E35: M4 | F35: 신규 | G35: - | H35: TensorRT-LLM / Triton | I35: RFP 표현은 'vLLM / TensorRT-LLM' 택일로 읽힘. 제품은 vLLM 기준(Triton은 백엔드 등록만, MLO-043) — vLLM 단일 제안으로 충족되는지 확인
A36: 31 | B36: AI 인프라 · 서빙 | C36: §3.2-① · §4.1 | D36: 모델 선정·비교 평가 및 라이선스 검토(한국어 품질, Llama Community License, Qwen 라이선스) | E36: M1 · M4 | F36: 솔루션에 포함 + 추가 개발 | G36: LLMOps | H36: 평가 셋 기반 비교 벤치마크 | I36: RFP 예시 모델은 2024년 세대 — 동급 최신 오픈소스 모델을 대안으로 비교 제시 가능. Llama-3.1-8B는 한국어 품질이 약해 Text-to-SQL 주력으로는 부적합할 수 있음. 모델 비교(LLMO-031)·평가(LLMO-051) 활용
A37: 32 | B37: AI 인프라 · 서빙 | C37: §3.2-② | D37: 임베딩·리랭커 모델 서빙(한영 혼용 기술 용어 대응) | E37: M4 | F37: 솔루션에 포함 + 추가 개발 | G37: MLOps · GraphRAG | H37: 다국어 임베딩(bge-m3 등), 리랭커(bge-reranker 계열) | I37: 임베딩 API(MLO-042 /v1/embeddings), 재순위화(GRAG-021). 엔지니어링 약어·단위 표현 검색 품질은 튜닝 필요
A38: 33 | B38: AI 인프라 · 서빙 | C38: §4.3 | D38: 서빙 모니터링·헬스 체크·장애 알림 | E38: M4~M6 | F38: 솔루션에 포함 + 추가 개발 | G38: LLMOps · MLOps | H38: Prometheus, DCGM exporter, 대시보드 | I38: GPU 온도·전력·사용률·메모리(LLMO-001~004), vLLM 메트릭(MLO-072), 임계 알림(MLO-075). 헬스 체크(MLO-038~041)는 명세상 '개발 필요' 항목
A39: 34 | B39: 하이브리드 RAG · Text-to-SQL | C39: §3.2-② (정량) | D39: Text-to-SQL 모듈 — MSSQL 연결, 자연어 → SQL 변환·실행 | E39: M4~M5 | F39: 솔루션에 포함 | G39: NL2SQL Agent | H39: NL2SQL Agent(ReAct·Lite 모드), sqlglot, ODBC Driver 18 | I39: MSSQL dialect 지원(NSQL-011), ReAct 다단 질의(NSQL-002~005), 단순 질의 고속 처리(NSQL-006)
A40: 35 | B40: 하이브리드 RAG · Text-to-SQL | C40: §3.2-② (정량) | D40: 스키마 프로파일링·컬럼 설명 보정(공학 용어·단위·코드값 설명, 조인 경로, 예시 질의-SQL 쌍) | E40: M4 | F40: 솔루션에 포함 + 추가 개발 | G40: NL2SQL Agent | H40: 스키마 설명 CSV·summary.json, few-shot 예시 | I40: FK·조인 마이닝(NSQL-012), 컬럼 프로파일(NSQL-013), 설명 편집(NSQL-018~019), 프롬프트 템플릿 교체(NSQL-020). 공학 용어·단위 설명 작성은 TFT와 공동 수행
...

Sheet 요약
A1: 개발 유형별 집계
A2: ※ 아래 수치는 '요구사항 매핑' 시트를 참조하는 수식입니다. 시트 수정 시 자동 반영됩니다.
A4: 개발 유형 | B4: 항목 수 | C4: 비중 | D4: 설명
A5: 솔루션에 포함 | B5: =COUNTIF('요구사항 매핑'!$F$6:$F$63,"솔루션에 포함") -> 7 | C5: =B5/$B$9 -> 0.12068966 | D5: 기존 제품 기능으로 즉시 대응 가능 (제안서 강점으로 부각)
A6: 추가 개발 | B6: =COUNTIF('요구사항 매핑'!$F$6:$F$63,"추가 개발") -> 8 | C6: =B6/$B$9 -> 0.13793103 | D6: 제품 기반 위에 연동·확장 개발이 필요한 항목
A7: 신규 | B7: =COUNTIF('요구사항 매핑'!$F$6:$F$63,"신규") -> 22 | C7: =B7/$B$9 -> 0.37931034 | D7: 제품과 무관하게 처음부터 구축·수행해야 하는 과업
A8: 복합(포함+추가/신규) | B8: =COUNTA('요구사항 매핑'!$F$6:$F$63)-B5-B6-B7 -> 21 | C8: =B8/$B$9 -> 0.36206897 | D8: 일부는 제품, 일부는 개발이 필요한 항목
A9: 합계 | B9: =SUM(B5:B8) -> 58 | C9: =B9/$B$9 -> 1
A11: 구분별 과업 수 (개발 유형별)
A12: 구분 | B12: 솔루션에 포함 | C12: 추가 개발 | D12: 신규 | E12: 포함 + 추가 개발 | F12: 합계
A13: 사업관리 | B13: =COUNTIFS('요구사항 매핑'!$B$6:$B$63,$A13,'요구사항 매핑'!$F$6:$F$63,"솔루션에 포함") -> 0 | C13: =COUNTIFS('요구사항 매핑'!$B$6:$B$63,$A13,'요구사항 매핑'!$F$6:$F$63,"추가 개발") -> 0 | D13: =COUNTIFS('요구사항 매핑'!$B$6:$B$63,$A13,'요구사항 매핑'!$F$6:$F$63,"신규") -> 4 | E13: =COUNTIFS('요구사항 매핑'!$B$6:$B$63,$A13,'요구사항 매핑'!$F$6:$F$63,"솔루션에 포함 + 추가 개발") -> 1 | F13: =SUM(B13:E13) -> 5
A14: 메타DB 설계 | B14: =COUNTIFS('요구사항 매핑'!$B$6:$B$63,$A14,'요구사항 매핑'!$F$6:$F$63,"솔루션에 포함") -> 0 | C14: =COUNTIFS('요구사항 매핑'!$B$6:$B$63,$A14,'요구사항 매핑'!$F$6:$F$63,"추가 개발") -> 0 | D14: =COUNTIFS('요구사항 매핑'!$B$6:$B$63,$A14,'요구사항 매핑'!$F$6:$F$63,"신규") -> 3 | E14: =COUNTIFS('요구사항 매핑'!$B$6:$B$63,$A14,'요구사항 매핑'!$F$6:$F$63,"솔루션에 포함 + 추가 개발") -> 1 | F14: =SUM(B14:E14) -> 4
A15: 파서 · ETL | B15: =COUNTIFS('요구사항 매핑'!$B$6:$B$63,$A15,'요구사항 매핑'!$F$6:$F$63,"솔루션에 포함") -> 0 | C15: =COUNTIFS('요구사항 매핑'!$B$6:$B$63,$A15,'요구사항 매핑'!$F$6:$F$63,"추가 개발") -> 0 | D15: =COUNTIFS('요구사항 매핑'!$B$6:$B$63,$A15,'요구사항 매핑'!$F$6:$F$63,"신규") -> 4 | E15: =COUNTIFS('요구사항 매핑'!$B$6:$B$63,$A15,'요구사항 매핑'!$F$6:$F$63,"솔루션에 포함 + 추가 개발") -> 4 | F15: =SUM(B15:E15) -> 8
A16: 정합성 검증 | B16: =COUNTIFS('요구사항 매핑'!$B$6:$B$63,$A16,'요구사항 매핑'!$F$6:$F$63,"솔루션에 포함") -> 0 | C16: =COUNTIFS('요구사항 매핑'!$B$6:$B$63,$A16,'요구사항 매핑'!$F$6:$F$63,"추가 개발") -> 0 | D16: =COUNTIFS('요구사항 매핑'!$B$6:$B$63,$A16,'요구사항 매핑'!$F$6:$F$63,"신규") -> 4 | E16: =COUNTIFS('요구사항 매핑'!$B$6:$B$63,$A16,'요구사항 매핑'!$F$6:$F$63,"솔루션에 포함 + 추가 개발") -> 1 | F16: =SUM(B16:E16) -> 5
A17: 파싱 예외 관리 | B17: =COUNTIFS('요구사항 매핑'!$B$6:$B$63,$A17,'요구사항 매핑'!$F$6:$F$63,"솔루션에 포함") -> 0 | C17: =COUNTIFS('요구사항 매핑'!$B$6:$B$63,$A17,'요구사항 매핑'!$F$6:$F$63,"추가 개발") -> 0 | D17: =COUNTIFS('요구사항 매핑'!$B$6:$B$63,$A17,'요구사항 매핑'!$F$6:$F$63,"신규") -> 2 | E17: =COUNTIFS('요구사항 매핑'!$B$6:$B$63,$A17,'요구사항 매핑'!$F$6:$F$63,"솔루션에 포함 + 추가 개발") -> 1 | F17: =SUM(B17:E17) -> 3
A18: AI 인프라 · 서빙 | B18: =COUNTIFS('요구사항 매핑'!$B$6:$B$63,$A18,'요구사항 매핑'!$F$6:$F$63,"솔루션에 포함") -> 2 | C18: =COUNTIFS('요구사항 매핑'!$B$6:$B$63,$A18,'요구사항 매핑'!$F$6:$F$63,"추가 개발") -> 0 | D18: =COUNTIFS('요구사항 매핑'!$B$6:$B$63,$A18,'요구사항 매핑'!$F$6:$F$63,"신규") -> 1 | E18: =COUNTIFS('요구사항 매핑'!$B$6:$B$63,$A18,'요구사항 매핑'!$F$6:$F$63,"솔루션에 포함 + 추가 개발") -> 5 | F18: =SUM(B18:E18) -> 8
A19: 하이브리드 RAG · Text-to-SQL | B19: =COUNTIFS('요구사항 매핑'!$B$6:$B$63,$A19,'요구사항 매핑'!$F$6:$F$63,"솔루션에 포함") -> 2 | C19: =COUNTIFS('요구사항 매핑'!$B$6:$B$63,$A19,'요구사항 매핑'!$F$6:$F$63,"추가 개발") -> 2 | D19: =COUNTIFS('요구사항 매핑'!$B$6:$B$63,$A19,'요구사항 매핑'!$F$6:$F$63,"신규") -> 0 | E19: =COUNTIFS('요구사항 매핑'!$B$6:$B$63,$A19,'요구사항 매핑'!$F$6:$F$63,"솔루션에 포함 + 추가 개발") -> 1 | F19: =SUM(B19:E19) -> 5
A20: 하이브리드 RAG · 비정형 | B20: =COUNTIFS('요구사항 매핑'!$B$6:$B$63,$A20,'요구사항 매핑'!$F$6:$F$63,"솔루션에 포함") -> 2 | C20: =COUNTIFS('요구사항 매핑'!$B$6:$B$63,$A20,'요구사항 매핑'!$F$6:$F$63,"추가 개발") -> 2 | D20: =COUNTIFS('요구사항 매핑'!$B$6:$B$63,$A20,'요구사항 매핑'!$F$6:$F$63,"신규") -> 0 | E20: =COUNTIFS('요구사항 매핑'!$B$6:$B$63,$A20,'요구사항 매핑'!$F$6:$F$63,"솔루션에 포함 + 추가 개발") -> 0 | F20: =SUM(B20:E20) -> 4
A21: 하이브리드 RAG · 오케스트레이션 | B21: =COUNTIFS('요구사항 매핑'!$B$6:$B$63,$A21,'요구사항 매핑'!$F$6:$F$63,"솔루션에 포함") -> 0 | C21: =COUNTIFS('요구사항 매핑'!$B$6:$B$63,$A21,'요구사항 매핑'!$F$6:$F$63,"추가 개발") -> 1 | D21: =COUNTIFS('요구사항 매핑'!$B$6:$B$63,$A21,'요구사항 매핑'!$F$6:$F$63,"신규") -> 0 | E21: =COUNTIFS('요구사항 매핑'!$B$6:$B$63,$A21,'요구사항 매핑'!$F$6:$F$63,"솔루션에 포함 + 추가 개발") -> 1 | F21: =SUM(B21:E21) -> 2
A22: 질의응답 포털 | B22: =COUNTIFS('요구사항 매핑'!$B$6:$B$63,$A22,'요구사항 매핑'!$F$6:$F$63,"솔루션에 포함") -> 0 | C22: =COUNTIFS('요구사항 매핑'!$B$6:$B$63,$A22,'요구사항 매핑'!$F$6:$F$63,"추가 개발") -> 1 | D22: =COUNTIFS('요구사항 매핑'!$B$6:$B$63,$A22,'요구사항 매핑'!$F$6:$F$63,"신규") -> 1 | E22: =COUNTIFS('요구사항 매핑'!$B$6:$B$63,$A22,'요구사항 매핑'!$F$6:$F$63,"솔루션에 포함 + 추가 개발") -> 2 | F22: =SUM(B22:E22) -> 4
A23: 가드레일 · 신뢰도 | B23: =COUNTIFS('요구사항 매핑'!$B$6:$B$63,$A23,'요구사항 매핑'!$F$6:$F$63,"솔루션에 포함") -> 0 | C23: =COUNTIFS('요구사항 매핑'!$B$6:$B$63,$A23,'요구사항 매핑'!$F$6:$F$63,"추가 개발") -> 0 | D23: =COUNTIFS('요구사항 매핑'!$B$6:$B$63,$A23,'요구사항 매핑'!$F$6:$F$63,"신규") -> 1 | E23: =COUNTIFS('요구사항 매핑'!$B$6:$B$63,$A23,'요구사항 매핑'!$F$6:$F$63,"솔루션에 포함 + 추가 개발") -> 2 | F23: =SUM(B23:E23) -> 3
A24: 보안 · 인프라 | B24: =COUNTIFS('요구사항 매핑'!$B$6:$B$63,$A24,'요구사항 매핑'!$F$6:$F$63,"솔루션에 포함") -> 1 | C24: =COUNTIFS('요구사항 매핑'!$B$6:$B$63,$A24,'요구사항 매핑'!$F$6:$F$63,"추가 개발") -> 2 | D24: =COUNTIFS('요구사항 매핑'!$B$6:$B$63,$A24,'요구사항 매핑'!$F$6:$F$63,"신규") -> 0 | E24: =COUNTIFS('요구사항 매핑'!$B$6:$B$63,$A24,'요구사항 매핑'!$F$6:$F$63,"솔루션에 포함 + 추가 개발") -> 2 | F24: =SUM(B24:E24) -> 5
A25: 통합 검증 · 안정화 | B25: =COUNTIFS('요구사항 매핑'!$B$6:$B$63,$A25,'요구사항 매핑'!$F$6:$F$63,"솔루션에 포함") -> 0 | C25: =COUNTIFS('요구사항 매핑'!$B$6:$B$63,$A25,'요구사항 매핑'!$F$6:$F$63,"추가 개발") -> 0 | D25: =COUNTIFS('요구사항 매핑'!$B$6:$B$63,$A25,'요구사항 매핑'!$F$6:$F$63,"신규") -> 2 | E25: =COUNTIFS('요구사항 매핑'!$B$6:$B$63,$A25,'요구사항 매핑'!$F$6:$F$63,"솔루션에 포함 + 추가 개발") -> 0 | F25: =SUM(B25:E25) -> 2
A26: 합계 | B26: =SUM(B13:B25) -> 7 | C26: =SUM(C13:C25) -> 8 | D26: =SUM(D13:D25) -> 22 | E26: =SUM(E13:E25) -> 21 | F26: =SUM(F13:F25) -> 58
A28: 주요 리스크 항목 (★)
A29: 순번 | B29: 항목 | C29: 개발 여부 | D29: 리스크 요지
A30: 3 | B30: §6 M1 · §4.3 GPU 서버·개발 환경 셋업(드라이버·CUDA·컨테이너 런타임), 폐쇄망 반입 패키지 구성(모델 가중치·wheel·이미지) | C30: 솔루션에 포함 + 추가 개발 | D30: GPU 서버가 '도입 예정' — 도입·반입 지연 시 M1 환경 셋업부터 전체 일정이 밀림
A31: 5 | B31: §6 M6 시스템 소스코드 일체 제출 | C31: 신규 | D31: '시스템 소스코드 일체' — 상용 플랫폼(Agent-X) 소스는 제출 불가, 제출 범위 협의 필요
A32: 10 | B32: §2-1 · §3.1-② PDS 파서(Excel) — 다단 헤더·복합 표 해석, 운전/설계 조건(Normal/Rated/Max 유량, P&T, Density, Viscosity, 열량), 조성, 부식 여유, 특수 사양 추출 | C32: 신규 | D32: 프로젝트별 서식(병합셀·다단 헤더) 다양성 — 서식 수에 비례해 파서 공수 증가, 6개월 내 5종 파서 + 튜닝
A33: 17 | B33: §3.1-② · §6 M2~M3 과거 프로젝트 데이터 대량 파싱 및 MSSQL 메타DB 적재 | C33: 신규 | D33: 과거 프로젝트 적재 범위(프로젝트·파일·서식 수) 미정 — 공수·견적 산정 불가
A34: 20 | B34: §3.1-③ (2) Instrument Index ↔ P&ID 도면 매핑 무결성 검증 | C34: 신규 | D34: P&ID는 5대 산출물 밖 — Tag 원천(설계 툴 추출본 vs 도면 PDF) 미정, 도면 인식이면 별도 과업
A35: 26 | B35: §3.2-① · §4.3 SLM/LLM 동시 구동 GPU 리소스 파티셔닝 방안 수립(L40S 48GB × 2) | C35: 솔루션에 포함 + 추가 개발 | D35: L40S 2장(MIG·NVLink 없음)에서 70B 4bit + SLM 동시 구동 — KV 캐시 여유가 작아 동시 사용자 수 제약
A36: 36 | B36: §3.2-② (정량) '0% 오차' 수치 조회 — 정확도 정의·검증 방식 수립(SQL 결과 원값 그대로 표기, LLM의 수치 재작성 금지) | C36: 추가 개발 | D36: '0% 오차' Text-to-SQL — SQL 변환 정확도 100%는 보장 불가, 검수 기준 재정의 필요
A37: 40 | B37: §3.2-② (비정형) · §4.2 MSSQL 비고란·L/L 텍스트 컬럼을 RAG 색인 소스로 수집 | C37: 추가 개발 | D37: RAGOps DB 소스에 MSSQL 미지원 — 커넥터 추가 개발
A38: 41 | B38: §3.2-② (비정형) 오픈소스 벡터DB(Milvus / pgvector 등) 연계 | C38: 추가 개발 | D38: '오픈소스 벡터DB(Milvus/pgvector 등)' 명시 — 코난 검색엔진 대체 인정 여부 미확인
A39: 49 | B39: §3.2-④ 수치 가드레일 — 답변 내 임계치(온도·압력·유량·재질) 값 추출 후 MSSQL 원값 대조, 불일치 시 차단/경고 | C39: 신규 | D39: 수치 가드레일(MSSQL 원값 대조·차단)은 제품에 없음 — 신규 개발, 차단 기준 정의가 TFT 의존
A40: - | B40: 사업 일정·예산 (§1.3 · §1.4) | C40: - | D40: 6개월에 파서 5종·정합성 엔진·예외 관리 UI·하이브리드 RAG·포털·가드레일을 모두 수행 — 사업 예산 '미정', 하자보수 '별도 협의'. M/M 산정 전 범위 고정 필요
A42: 발주처 확인 요청 사항 (제안 정밀도 향상을 위해 필요)
A43: 1 | B43: 과거 프로젝트 적재 범위 — 대상 프로젝트 수, 산출물별 파일 수, 서식 종류, 스캔 PDF 비중
A44: 2 | B44: P&ID Tag 원천 형태 — 설계 툴(SPPID·AVEVA 등) 추출 리스트 제공 가능 여부, 도면 PDF/CAD만 있는지
...

Sheet 기술 요소 매핑
A1: 기술 요소 매핑 (계층별 기술 스택)
A2: 제공 형태: 제품 = Agent-X 기능 / 오픈소스 = 신규 도입 OSS / 발주사 제공 = RFP상 당사 제공 / 신규 개발 = 커스텀 개발. '관련 과업'은 '요구사항 매핑' 시트 순번
A4: 계층 | B4: 기술 요소 | C4: 적용 기술 | D4: 제공 형태 | E4: 관련 과업 | F4: 비고
A5: 데이터 원천 | B5: 파일 저장소 | C5: 사내 파일서버(SMB/NFS) — RAGOps 문서 저장소 연결(RAG-110) | D5: 발주사 제공 | E5: 16, 46 | F5: 원천 파일 링크 경로 규칙을 메타DB 출처 컬럼과 통일
A6: 파싱 | B6: Excel 파서 | C6: pandas, openpyxl | D6: 오픈소스 | E6: 10, 12, 13, 14 | F6: 병합셀 해제·다단 헤더 경로 평탄화·서식별 매핑 규칙(YAML)
A7: 파싱 | B7: Word 파서 | C7: python-docx | D7: 오픈소스 | E7: 12, 15 | F7: 표 병합셀 처리
A8: 파싱 | B8: PDF 텍스트·표 | C8: PyMuPDF, pdfplumber, Camelot | D8: 오픈소스 | E8: 11 | F8: 텍스트 PDF 대상
A9: 파싱 | B9: Form PDF | C9: pypdf (AcroForm 필드) | D9: 오픈소스 | E9: 14 | F9: 평탄화된 PDF는 OCR 폴백
A10: 파싱 | B10: OCR · VLM | C10: DOC-AI OCR(RAGA-011), 표 왜곡 시 이미지 재판독(RAGA-014) | D10: 제품 | E10: 11, 14 | F10: 스캔본 대상
A11: 파싱 | B11: LLM 구조화 추출 | C11: LLM 노드 구조화 출력(AGT-013), 문서 추출 노드(AGT-019) | D11: 제품 | E11: 15, 21 | F11: L/L 서술형 리포트 필드 추출
A12: 파싱 | B12: 단위 변환 | C12: pint | D12: 오픈소스 | E12: 8, 49 | F12: SI 기준 환산값 저장
A13: ETL | B13: 오케스트레이션 | C13: RAGOps 작업 등록·파이프라인·스케줄 엔진(RAG-122·123·126) | D13: 제품 | E13: 16 | F13: 재시도·실행 이력(RAG-128·131)
A14: ETL | B14: MSSQL 적재 | C14: SQLAlchemy, pyodbc(fast_executemany), BCP | D14: 오픈소스 | E14: 16, 17 | F14: Staging → Core 2단 적재
A15: 메타DB | B15: RDBMS | C15: Microsoft SQL Server | D15: 발주사 제공 | E15: 6 ~ 9 | F15: 버전·에디션 확인 필요
... A34: 보안 | B34: 권한 · 감사 | C34: RBAC(LLMO-076), 권한 필터(GRAG-017), 감사 로그(GRAG-028) | D34: 제품 | E34: 54, 55 | F34: SQL 단위 감사 기록은 개발
A36: GPU 리소스 파티셔닝 안 (NVIDIA L40S 48GB × 2, §4.3)
A37: ※ 수치는 공개 체크포인트 크기 기준 추정치(GB) — M1 PoC에서 실측 후 확정. L40S는 MIG 미지원이므로 vLLM gpu-memory-utilization으로 프로세스별 분할
A38: 안 / GPU | B38: 구동 모델 | C38: 용도 | D38: 정밀도 | E38: 할당 VRAM(GB) | F38: 비고
A39: 1안 · GPU0 | B39: Llama-3.1-70B (TP=2, shard 0) | C39: 종합 답변·L/L 요약 | D39: INT4 AWQ | E39: 28.8 | F39: util 0.60 — 가중치 약 20GB + KV 약 9GB
A40: 1안 · GPU0 | B40: 임베딩 + 리랭커 | C40: 벡터 검색·재순위화 | D40: FP16 | E40: 6 | F40: bge-m3·리랭커 상주
A41: 1안 · GPU1 | B41: Llama-3.1-70B (TP=2, shard 1) | C41: 종합 답변·L/L 요약 | D41: INT4 AWQ | E41: 28.8 | F41: util 0.60
A42: 1안 · GPU1 | B42: Qwen2.5-14B-Instruct | C42: Text-to-SQL·라우팅·파싱 보조 | D42: INT4 AWQ | E42: 16.8 | F42: util 0.35 — 가중치 약 10GB + KV 약 6GB
A43: 2안 · GPU0 | B43: Qwen2.5-32B-Instruct | C43: Text-to-SQL·종합 답변(주력) | D43: INT4 AWQ | E43: 40.8 | F43: util 0.85 — KV 여유 커서 동시 사용자 유리
A44: 2안 · GPU1 | B44: Qwen2.5-14B 또는 Llama-3.1-8B | C44: 라우팅·L/L 구조화 추출 | D44: INT4 AWQ | E44: 16.8 | F44: util 0.35
A45: 2안 · GPU1 | B45: 임베딩 + 리랭커 + OCR/VLM 배치 | C45: 검색·파싱 | D45: FP16 | E45: 20 | F45: 70B는 필요 시 로드/언로드(LLMO-011)로 야간 배치 전환
A47: GPU 합계 | B47: 할당 합계(GB) | C47: 용량(GB) | D47: 여유(GB) | E47: 사용률
A48: 1안 · GPU0 | B48: =SUMIF($A$39:$A$45,A48,$E$39:$E$45) -> 34.8 | C48: 48 | D48: =C48-B48 -> 13.2 | E48: =B48/C48 -> 0.725
A49: 1안 · GPU1 | B49: =SUMIF($A$39:$A$45,A49,$E$39:$E$45) -> 45.6 | C49: 48 | D49: =C49-B49 -> 2.4 | E49: =B49/C49 -> 0.95
A50: 2안 · GPU0 | B50: =SUMIF($A$39:$A$45,A50,$E$39:$E$45) -> 40.8 | C50: 48 | D50: =C50-B50 -> 7.2 | E50: =B50/C50 -> 0.85
A51: 2안 · GPU1 | B51: =SUMIF($A$39:$A$45,A51,$E$39:$E$45) -> 36.8 | C51: 48 | D51: =C51-B51 -> 11.2 | E51: =B51/C51 -> 0.76666667
A52: ※ 파란 글씨 = 추정 입력값(L40S 48GB 사양, 모델별 할당 추정). 여유분은 CUDA 컨텍스트·버퍼(프로세스당 약 0.5~1GB)에 사용
